Workbook

Sheet Лист1
A1: ФИО | B1: Блок | C1: Принадлежность | D1: Структурное подразделение | E1: Должность | F1: ФИО | G1: ИНН | H1: Количество штатных единиц
A2: Титов Владимир Павлович | B2: Администрация | C2: Администрация | D2: Администрация | E2: Генеральный директор | F2: Титов Владимир Павлович | G2: =+VLOOKUP(F2,[1]Лист_1!$A:$C,2,0) -> 860502580073 | H2: 1
A3: Майорова Мария Сергеевна | B3: Администрация | C3: Администрация | D3: Администрация | E3: Первый заместитель генерального директора | F3: Майорова Мария Сергеевна | G3: =+VLOOKUP(F3,[1]Лист_1!$A:$C,2,0) -> 213002549315 | H3: 1
A4: Полищученко Владислав Анатольевич | B4: Администрация | C4: Администрация | D4: Администрация | E4: Заместитель генерального директора | F4: Полищученко Владислав Анатольевич | G4: =+VLOOKUP(F4,[1]Лист_1!$A:$C,2,0) -> 575306392458 | H4: 1
A5: Кустов Николай Сергеевич | B5: Администрация | C5: Администрация | D5: Администрация | E5: Заместитель генерального директора | F5: Кустов Николай Сергеевич | G5: =+VLOOKUP(F5,[1]Лист_1!$A:$C,2,0) -> 231518985850 | H5: 1
A6: Лазуткин Юрий Викторович | B6: Администрация | C6: Администрация | D6: Администрация | E6: Заместитель генерального директора | F6: Лазуткин Юрий Викторович | G6: =+VLOOKUP(F6,[1]Лист_1!$A:$C,2,0) -> 672205972178 | H6: 1
A7: Григорян Артем Вазгенович | B7: Администрация | C7: Администрация | D7: Администрация | E7: Заместитель генерального директора-руководитель контрактной службы | F7: Григорян Артем Вазгенович | G7: =+VLOOKUP(F7,[1]Лист_1!$A:$C,2,0) -> 770507962337 | H7: 1
A8: Курский Андрей Юрьевич | B8: Администрация | C8: Администрация | D8: Администрация | E8: Финансовый директор | F8: Курский Андрей Юрьевич | G8: =+VLOOKUP(F8,[1]Лист_1!$A:$C,2,0) -> 771902605095 | H8: 1
A9: Измайлов Станислав Владимирович | B9: Администрация | C9: Администрация | D9: Администрация | E9: Технический директор | F9: Измайлов Станислав Владимирович | G9: =+VLOOKUP(F9,[1]Лист_1!$A:$C,2,0) -> 772835122694 | H9: 1
A10: Кукушкина Валерия Павловна | B10: Администрация | C10: Администрация | D10: Администрация | E10: Административный директор | F10: Кукушкина Валерия Павловна | G10: =+VLOOKUP(F10,[1]Лист_1!$A:$C,2,0) -> 504026087462 | H10: 1
A11: Мураткина Валерия Александровна | B11: Администрация | C11: Администрация | D11: Администрация | E11: Директор по управлению персоналом | F11: Мураткина Валерия Александровна | G11: =+VLOOKUP(F11,[1]Лист_1!$A:$C,2,0) -> 862201308007 | H11: 1
A12: Курганская Марина Владимировна | B12: Администрация | C12: Администрация | D12: Администрация | E12: Директор по коммуникациям | F12: Курганская Марина Владимировна | G12: =+VLOOKUP(F12,[1]Лист_1!$A:$C,2,0) -> 771596412912 | H12: 1
A13: ВАКАНСИЯ | B13: Администрация | C13: Администрация | D13: Администрация | E13: Советник руководителя | F13: ВАКАНСИЯ | H13: 1
A14: Мараева Ксения Александровна | B14: Администрация | C14: Прочие | D14: Администрация | E14: Советник руководителя | F14: Мараева Ксения Александровна | G14: =+VLOOKUP(F14,[1]Лист_1!$A:$C,2,0) -> 667479112755 | H14: 0.5
A15: ВАКАНСИЯ | B15: Администрация | C15: Администрация | D15: Администрация | E15: Советник руководителя | F15: ВАКАНСИЯ | H15: 0.5
A16: ВАКАНСИЯ | B16: Администрация | C16: Администрация | D16: Администрация | E16: Советник руководителя | F16: ВАКАНСИЯ | H16: 1
A17: Иванов Алексей Валерьевич | B17: Администрация | C17: Кустов | D17: Администрация | E17: Советник руководителя | F17: Иванов Алексей Валерьевич | G17: =+VLOOKUP(F17,[1]Лист_1!$A:$C,2,0) -> 920451393954 | H17: 1
H18: =SUM(H2:H17) -> 15
A19: Пономаренко Сергей Александрович | B19: Кустов | C19: Кустов | D19: Аналитический центр | E19: Начальник центра | F19: Пономаренко Сергей Александрович | G19: =+VLOOKUP(F19,[1]Лист_1!$A:$C,2,0) -> 344407771223 | H19: 1
A20: Шарапов Александр Михайлович | B20: Кустов | C20: Кустов | D20: Отдел анализа данных | E20: Начальник отдела | F20: Шарапов Александр Михайлович | G20: =+VLOOKUP(F20,[1]Лист_1!$A:$C,2,0) -> 645112271345 | H20: 1
A21: Нестеров Степан Владимирович | B21: Кустов | C21: Кустов | D21: Отдел анализа данных | E21: Заместитель начальника отдела | F21: ВАКАНСИЯ | H21: 1
A22: ВАКАНСИЯ | B22: Кустов | C22: Кустов | D22: Отдел анализа данных | E22: Главный аналитик | F22: ВАКАНСИЯ | H22: 1
A23: Терехова Любовь Андреевна | B23: Кустов | C23: Кустов | D23: Отдел анализа данных | E23: Ведущий аналитик | F23: Терехова Любовь Андреевна | G23: =+VLOOKUP(F23,[1]Лист_1!$A:$C,2,0) -> 431207363154 | H23: 1
A24: Бабенков Павел Алексеевич | B24: Кустов | C24: Кустов | D24: Отдел анализа данных | E24: Ведущий аналитик | F24: Бабенков Павел Алексеевич | G24: =+VLOOKUP(F24,[1]Лист_1!$A:$C,2,0) -> 164906291910 | H24: 1
A25: Иванов Максим Арсеньевич | B25: Кустов | C25: Кустов | D25: Отдел анализа данных | E25: Ведущий аналитик | F25: Иванов Максим Арсеньевич | G25: =+VLOOKUP(F25,[1]Лист_1!$A:$C,2,0) -> 772394417701 | H25: 1
A26: Гуленков Вадим Алексеевич | B26: Кустов | C26: Кустов | D26: Отдел макромоделирования | E26: Начальник отдела | F26: Гуленков Вадим Алексеевич | G26: =+VLOOKUP(F26,[1]Лист_1!$A:$C,2,0) -> 772019771460 | H26: 1
A27: Кураксин Антон Александрович | B27: Кустов | C27: Кустов | D27: Отдел макромоделирования | E27: Главный аналитик | F27: Кураксин Антон Александрович | G27: =+VLOOKUP(F27,[1]Лист_1!$A:$C,2,0) -> 621103311986 | H27: 1
A28: Галяткин Дмитрий Васильевич | B28: Кустов | C28: Кустов | D28: Отдел макромоделирования | E28: Ведущий аналитик | F28: Галяткин Дмитрий Васильевич | G28: =+VLOOKUP(F28,[1]Лист_1!$A:$C,2,0) -> 772033456710 | H28: 1
A29: Абашкина Марина Алексеевна | B29: Кустов | C29: Кустов | D29: Отдел макромоделирования | E29: Ведущий аналитик | F29: Абашкина Марина Алексеевна | G29: =+VLOOKUP(F29,[1]Лист_1!$A:$C,2,0) -> 772148180169 | H29: 1
A30: Рустанович Анна Павловна | B30: Кустов | C30: Кустов | D30: Отдел макромоделирования | E30: Ведущий аналитик | F30: Рустанович Анна Павловна | G30: =+VLOOKUP(F30,[1]Лист_1!$A:$C,2,0) -> 772831714107 | H30: 1
A31: Журбинский Роман Игоревич | B31: Кустов | C31: Кустов | D31: Группа исследований и автоматизации аналитики | E31: Начальник группы | F31: ВАКАНСИЯ | H31: 1
A32: Марковский Валентин Александрович | B32: Кустов | C32: Кустов | D32: Группа исследований и автоматизации аналитики | E32: Главный аналитик | F32: Марковский Валентин Александрович | G32: =+VLOOKUP(F32,[1]Лист_1!$A:$C,2,0) -> 231138949422 | H32: 1
A33: Назаров Михаил Сергеевич | B33: Кустов | C33: Кустов | D33: Группа исследований и автоматизации аналитики | E33: Главный аналитик | F33: Назаров Михаил Сергеевич | G33: =+VLOOKUP(F33,[1]Лист_1!$A:$C,2,0) -> 783904093170 | H33: 1
A34: Слученкова Галина Юрьевна | B34: Кустов | C34: Кустов | D34: Группа исследований и автоматизации аналитики | E34: Главный аналитик | F34: Слученкова Галина Юрьевна | G34: =+VLOOKUP(F34,[1]Лист_1!$A:$C,2,0) -> 772832247293 | H34: 1
A35: Больдясов Алексей Ильич | B35: Кустов | C35: Кустов | D35: Группа исследований и автоматизации аналитики | E35: Ведущий аналитик | F35: Больдясов Алексей Ильич | G35: =+VLOOKUP(F35,[1]Лист_1!$A:$C,2,0) -> 524926672003 | H35: 1
A36: Ивенский Георгий Андреевич | B36: Кустов | C36: Кустов | D36: Дирекция транспортных проектов | E36: Начальник дирекции | F36: Ивенский Георгий Андреевич | G36: =+VLOOKUP(F36,[1]Лист_1!$A:$C,2,0) -> 771617124474 | H36: 1
A37: Сергеев Дмитрий Владимирович | B37: Кустов | C37: Кустов | D37: Дирекция транспортных проектов | E37: Советник руководителя | F37: Сергеев Дмитрий Владимирович | G37: =+VLOOKUP(F37,[1]Лист_1!$A:$C,2,0) -> 710708777304 | H37: 1
A38: Свириденков Владимир Эдуардович | B38: Кустов | C38: Кустов | D38: Дирекция транспортных проектов | E38: Советник руководителя | F38: Свириденков Владимир Эдуардович | G38: =+VLOOKUP(F38,[1]Лист_1!$A:$C,2,0) -> 504602439283 | H38: 1
A39: Дронов Антон Павлович | B39: Кустов | C39: Кустов | D39: Центр развития транспортно-пересадочных узлов | E39: Начальник центра | F39: Дронов Антон Павлович | G39: =+VLOOKUP(F39,[1]Лист_1!$A:$C,2,0) -> 772023693736 | H39: 1
A40: Вдовина Ирина Алексеевна | B40: Кустов | C40: Кустов | D40: Отдел сопровождения транспортно-пересадочных узлов | E40: Начальник отдела | F40: Вдовина Ирина Алексеевна | G40: =+VLOOKUP(F40,[1]Лист_1!$A:$C,2,0) -> 502723791545 | H40: 1
...
